<?xml version="1.0" encoding="utf-8"?>
<!-- This URDF was automatically created by SolidWorks to URDF Exporter! Originally created by Stephen Brawner (brawner@gmail.com) 
     Commit Version: 1.6.0-1-g15f4949  Build Version: 1.6.7594.29634
     For more information, please see http://wiki.ros.org/sw_urdf_exporter -->
<robot
  name="diff2">


<link name="base_footprint">
    
    <visual>
        <origin xyz="0 0 0" rpy="0 0 0" />
        <geometry>
            <box size="0.001 0.001 0.001" />
        </geometry>
    </visual>
  </link>

  <gazebo reference="base_footprint">
    <turnGravityOff>false</turnGravityOff>
  </gazebo>


<joint name="base_footprint_joint" type="fixed">
    <parent link="base_footprint" />
    <child link="base_link" />
    <origin xyz="0 0 0.15" rpy="0 0 0"/>
</joint> 

  <link
    name="base_link">
    <inertial>
      <origin
        xyz="0.0162861872681784 0 -0.0759700833037699"
        rpy="0 0 0" />
      <mass
        value="5" />
      <inertia
        ixx="1.7243164244166"
        ixy="2.09887951955896E-08"
        ixz="0.0126038892096571"
        iyy="1.81721517328364"
        iyz="-1.68636582815318E-17"
        izz="3.33641567551096" />
    </inertial>
    <visual>
      <origin
        xyz="0 0 0"
        rpy="0 0 0" />
      <geometry>
        <mesh
          filename="package://diff2/meshes/base_link.STL" />
      </geometry>
      <material
        name="">
        <color
          rgba="0.792156862745098 0.819607843137255 0.933333333333333 1" />
      </material>
    </visual>
    <collision>
      <origin
        xyz="0 0 0"
        rpy="0 0 0" />
      <geometry>
        <mesh
          filename="package://diff2/meshes/base_link.STL" />
      </geometry>
    </collision>
  </link>
  <link
    name="llink">
    <inertial>
      <origin
        xyz="1.3878E-17 0.76237 -8.6736E-18"
        rpy="0 0 0" />
      <mass
        value="4.3532" />
      <inertia
        ixx="0.032812"
        ixy="1.4574E-20"
        ixz="-3.2387E-18"
        iyy="0.063522"
        iyz="2.3256E-20"
        izz="0.032812" />
    </inertial>
    <visual>
      <origin
        xyz="0 0 0"
        rpy="0 0 0" />
      <geometry>
        <mesh
          filename="package://diff2/meshes/llink.STL" />
      </geometry>
      <material
        name="">
        <color
          rgba="0.79216 0.81961 0.93333 1" />
      </material>
    </visual>
    <collision>
      <origin
        xyz="0 0 0"
        rpy="0 0 0" />
      <geometry>
        <mesh
          filename="package://diff2/meshes/llink.STL" />
      </geometry>
    </collision>
  </link>
  <joint
    name="ljoint"
    type="continuous">
    <origin
      xyz="0.020146 -0.396 -0.075"
      rpy="0 0 0" />
    <parent
      link="base_link" />
    <child
      link="llink" />
    <axis
      xyz="0 1 0" />
    <limit
      effort="2"
      velocity="2" />
  </joint>
  <link
    name="rLink">
    <inertial>
      <origin
        xyz="0 -0.76237 0"
        rpy="0 0 0" />
      <mass
        value="4.3532" />
      <inertia
        ixx="0.032812"
        ixy="2.5089E-19"
        ixz="1.2489E-18"
        iyy="0.063522"
        iyz="-4.6514E-19"
        izz="0.032812" />
    </inertial>
    <visual>
      <origin
        xyz="0 0 0"
        rpy="0 0 0" />
      <geometry>
        <mesh
          filename="package://diff2/meshes/rLink.STL" />
      </geometry>
      <material
        name="">
        <color
          rgba="0.79216 0.81961 0.93333 1" />
      </material>
    </visual>
    <collision>
      <origin
        xyz="0 0 0"
        rpy="0 0 0" />
      <geometry>
        <mesh
          filename="package://diff2/meshes/rLink.STL" />
      </geometry>
    </collision>
  </link>
  <joint
    name="rjoint"
    type="continuous">
    <origin
      xyz="0.020146 0.393 -0.075"
      rpy="0 0 0" />
    <parent
      link="base_link" />
    <child
      link="rLink" />
    <axis
      xyz="0 1 0" />
    <limit
      effort="2"
      velocity="2" />
  </joint>
  <link
    name="cf">
    <inertial>
      <origin
        xyz="2.77555756156289E-17 0 0.0403097826086957"
        rpy="0 0 0" />
      <mass
        value="0.543806415844046" />
      <inertia
        ixx="0.000673296897339542"
        ixy="1.78263908775195E-36"
        ixz="-2.46678960960954E-20"
        iyy="0.000673296897339541"
        iyz="-1.19960995655283E-36"
        izz="0.000462084724515222" />
    </inertial>
    <visual>
      <origin
        xyz="0 0 0"
        rpy="0 0 0" />
      <geometry>
        <mesh
          filename="package://diff2/meshes/cf.STL" />
      </geometry>
      <material
        name="">
        <color
          rgba="0.792156862745098 0.819607843137255 0.933333333333333 1" />
      </material>
    </visual>
    <collision>
      <origin
        xyz="0 0 0"
        rpy="0 0 0" />
      <geometry>
        <mesh
          filename="package://diff2/meshes/cf.STL" />
      </geometry>
    </collision>
  </link>
  <joint
    name="cj"
    type="continuous">
    <origin
      xyz="0.24515 0 -0.22875"
      rpy="0 0 0" />
    <parent
      link="base_link" />
    <child
      link="cf" />
    <axis
      xyz="0 0 1" />
  </joint>
  <link
    name="cr">
    <inertial>
      <origin
        xyz="0 0 0.0403097826086957"
        rpy="0 0 0" />
      <mass
        value="0.543806415844046" />
      <inertia
        ixx="0.000673296897339542"
        ixy="1.78263908775195E-36"
        ixz="-2.46678960960954E-20"
        iyy="0.000673296897339541"
        iyz="-1.19960995655283E-36"
        izz="0.000462084724515222" />
    </inertial>
    <visual>
      <origin
        xyz="0 0 0"
        rpy="0 0 0" />
      <geometry>
        <mesh
          filename="package://diff2/meshes/cr.STL" />
      </geometry>
      <material
        name="">
        <color
          rgba="0.792156862745098 0.819607843137255 0.933333333333333 1" />
      </material>
    </visual>
    <collision>
      <origin
        xyz="0 0 0"
        rpy="0 0 0" />
      <geometry>
        <mesh
          filename="package://diff2/meshes/cr.STL" />
      </geometry>
    </collision>
  </link>
  <joint
    name="cjr"
    type="continuous">
    <origin
      xyz="-0.20485 0 -0.22875"
      rpy="0 0 0" />
    <parent
      link="base_link" />
    <child
      link="cr" />
    <axis
      xyz="0 0 1" />
  </joint>
  <link
    name="sl">
    <inertial>
      <origin
        xyz="-2.77555756156289E-17 -1.38777878078145E-17 -0.0925"
        rpy="0 0 0" />
      <mass
        value="6.27027571375136" />
      <inertia
        ixx="0.0378582462769977"
        ixy="4.17609541726232E-34"
        ixz="1.83736982455739E-18"
        iyy="0.0335853876106764"
        iyz="2.34338648826141E-34"
        izz="0.0356769361704841" />
    </inertial>
    <visual>
      <origin
        xyz="0 0 0"
        rpy="0 0 0" />
      <geometry>
        <mesh
          filename="package://diff2/meshes/sl.STL" />
      </geometry>
      <material
        name="">
        <color
          rgba="0.792156862745098 0.819607843137255 0.933333333333333 1" />
      </material>
    </visual>
    <collision>
      <origin
        xyz="0 0 0"
        rpy="0 0 0" />
      <geometry>
        <mesh
          filename="package://diff2/meshes/sl.STL" />
      </geometry>
    </collision>
  </link>
  <joint
    name="sj"
    type="fixed">
    <origin
      xyz="0.22875 0 0.156"
      rpy="0 0 0" />
    <parent
      link="base_link" />
    <child
      link="sl" />
    <axis
      xyz="0 1 0" />
    <limit
      lower="0"
      upper="0"
      effort="0"
      velocity="0" />
  </joint>

<joint name="hokuyo_joint" type="fixed">
    <parent link="base_link" />
    <child link="hokuyo_link" />
    <origin xyz="0 0 0.5" />
</joint>

<link name="hokuyo_link" >
    
    <visual>
        <origin xyz="0 0 0" rpy="0 0 0" />
        <geometry>
            <box size="0.05 0.05 0.05"/>
        </geometry>
      <material name="Blue" />
    </visual>

</link>

<gazebo reference="base_link">
    <material>Gazebo/DarkGrey</material>
  </gazebo>

  <gazebo reference="llink">
    <mu1>0.1</mu1>
    <mu2>0.1</mu2>
    <kp>500000.0</kp>
    <kd>10.0</kd>
    <minDepth>0.001</minDepth>
    <maxVel>5</maxVel>
    <fdir1>1 0 0</fdir1>
    <material>Gazebo/FlatBlack</material>
  </gazebo>

  <gazebo reference="rLink">
    <mu1>0.1</mu1>
    <mu2>0.1</mu2>
    <kp>500000.0</kp>
    <kd>10.0</kd>
    <minDepth>0.001</minDepth>
    <maxVel>5</maxVel>
    <fdir1>1 0 0</fdir1>
    <material>Gazebo/FlatBlack</material>
  </gazebo>

  <gazebo reference="cf">
    <mu1>0.1</mu1>
    <mu2>0.1</mu2>
    <kp>1000000.0</kp>
    <kd>100.0</kd>
    <minDepth>0.001</minDepth>
    <maxVel>5</maxVel>
    <material>Gazebo/FlatBlack</material>
  </gazebo>

  <gazebo reference="cr">
    <mu1>0.1</mu1>
    <mu2>0.1</mu2>
    <kp>1000000.0</kp>
    <kd>100.0</kd>
    <minDepth>0.001</minDepth>
    <maxVel>5</maxVel>
    <material>Gazebo/FlatBlack</material>
  </gazebo>


<!--wheel plugins and sensor plugins-->

<gazebo reference="hokuyo_link">
    <material>Gazebo/Blue</material>
    <turnGravityOff>false</turnGravityOff>
    <sensor type="ray" name="head_hokuyo_sensor">
      <pose>4 0 0 0 0 0</pose>
      <visualize>true</visualize>
      <update_rate>40</update_rate>
      <ray>
        <scan>
          <horizontal>
            <samples>720</samples>
            <resolution>1</resolution>
            <min_angle>-1.570796</min_angle>
            <max_angle>1.570796</max_angle>
          </horizontal>
        </scan>
        <range>
          <min>0.10</min>
          <max>10.0</max>
          <resolution>0.001</resolution>
        </range>
      </ray>
      <plugin name="gazebo_ros_head_hokuyo_controller" filename="libgazebo_ros_laser.so">
        <topicName>/scan</topicName>
        <frameName>hokuyo_link</frameName>
      </plugin>
    </sensor>
</gazebo>


<!-- Differential drive controller  -->
<gazebo>
    <plugin name="differential_drive_controller" filename="libgazebo_ros_diff_drive.so">

       <rosDebugLevel>Debug</rosDebugLevel>
      <publishWheelTF>false</publishWheelTF>
      <robotNamespace>/</robotNamespace>
      <publishTf>1</publishTf>
      <publishWheelJointState>false</publishWheelJointState>
      <alwaysOn>true</alwaysOn>
      <updateRate>30</updateRate>
      <leftJoint>ljoint</leftJoint>
      <rightJoint>rjoint</rightJoint>
      <wheelSeparation>0.35</wheelSeparation>
      <wheelDiameter>0.15</wheelDiameter>
      <broadcastTF>1</broadcastTF>
      <wheelTorque>100</wheelTorque>
      <wheelAcceleration>10</wheelAcceleration>
      <commandTopic>cmd_vel</commandTopic>
      <odometryFrame>odom</odometryFrame> 
      <odometryTopic>odom</odometryTopic> 
      <odometrySource>1</odometrySource>
      <publishOdomTF>true</publishOdomTF>
      <robotBaseFrame>base_footprint</robotBaseFrame>
      
    </plugin>
</gazebo> 


</robot>
